from rest_framework.test import APITestCase

from django.core.exceptions import ValidationError
from users.models import CustomUser
from .models import Ad, Category


class AdModelTest(APITestCase):
    def setUp(self):
        self.user = CustomUser.objects.create_user(
            email="test_user@mail.com",
            password="userword",
            display_name="test_user",
            account_type="individual",
        )
        self.base_category = Category.objects.create(name="All Categories", parent=None)
        self.leaf_category = Category.objects.create(
            name="Category 1", parent=self.base_category
        )
        self.ad_data = {
            "title": "Test Ad",
            "description": "This is a test ad.",
            "price": 100,
            "created_by": self.user,
            "images": ["image1.jpg", "image2.jpg"],
        }

    def test_create_valid_category_ad(self):
        ad = Ad.objects.create(**self.ad_data, category=self.leaf_category)
        self.assertEqual(ad.title, "Test Ad")
        self.assertEqual(ad.description, "This is a test ad.")
        self.assertEqual(ad.price, 100)
        self.assertEqual(ad.category, self.leaf_category)
        self.assertEqual(ad.created_by, self.user)
        self.assertEqual(ad.images, ["image1.jpg", "image2.jpg"])
        self.assertFalse(ad.is_highlight())

    def test_create_invalid_category_ad(self):
        self.assertRaises(
            ValidationError,
            Ad.objects.create,
            **self.ad_data,
            category=self.base_category
        )
